2024-10-25 00:37:21,452 ERROR: Server Error: 500 Internal Server Error: The server encountered an internal error and was unable to complete your request. Either the server is overloaded or there is an error in the application. [in /home/runner/BonusManager360/app.py:150]
2024-10-25 00:37:32,661 ERROR: Page not found: 404 Not Found: The requested URL was not found on the server. If you entered the URL manually please check your spelling and try again. [in /home/runner/BonusManager360/app.py:144]
2024-10-25 00:37:33,374 ERROR: Exception on /favicon.ico [GET] [in /home/runner/BonusManager360/.pythonlibs/lib/python3.11/site-packages/flask/app.py:825]
Traceback (most recent call last):
  File "/home/runner/BonusManager360/.pythonlibs/lib/python3.11/site-packages/flask/app.py", line 867, in full_dispatch_request
    rv = self.dispatch_request()
         ^^^^^^^^^^^^^^^^^^^^^^^
  File "/home/runner/BonusManager360/.pythonlibs/lib/python3.11/site-packages/flask/app.py", line 841, in dispatch_request
    self.raise_routing_exception(req)
  File "/home/runner/BonusManager360/.pythonlibs/lib/python3.11/site-packages/flask/app.py", line 450, in raise_routing_exception
    raise request.routing_exception  # type: ignore
    ^^^^^^^^^^^^^^^^^^^^^^^^^^^^^^^
  File "/home/runner/BonusManager360/.pythonlibs/lib/python3.11/site-packages/flask/ctx.py", line 353, in match_request
    result = self.url_adapter.match(return_rule=True)  # type: ignore
             ^^^^^^^^^^^^^^^^^^^^^^^^^^^^^^^^^^^^^^^^
  File "/home/runner/BonusManager360/.pythonlibs/lib/python3.11/site-packages/werkzeug/routing/map.py", line 624, in match
    raise NotFound() from None
werkzeug.exceptions.NotFound: 404 Not Found: The requested URL was not found on the server. If you entered the URL manually please check your spelling and try again.

During handling of the above exception, another exception occurred:

Traceback (most recent call last):
  File "/home/runner/BonusManager360/.pythonlibs/lib/python3.11/site-packages/flask/app.py", line 1455, in wsgi_app
    response = self.full_dispatch_request()
               ^^^^^^^^^^^^^^^^^^^^^^^^^^^^
  File "/home/runner/BonusManager360/.pythonlibs/lib/python3.11/site-packages/flask/app.py", line 869, in full_dispatch_request
    rv = self.handle_user_exception(e)
         ^^^^^^^^^^^^^^^^^^^^^^^^^^^^^
  File "/home/runner/BonusManager360/.pythonlibs/lib/python3.11/site-packages/flask/app.py", line 752, in handle_user_exception
    return self.handle_http_exception(e)
           ^^^^^^^^^^^^^^^^^^^^^^^^^^^^^
  File "/home/runner/BonusManager360/.pythonlibs/lib/python3.11/site-packages/flask/app.py", line 727, in handle_http_exception
    return self.ensure_sync(handler)(e)
           ^^^^^^^^^^^^^^^^^^^^^^^^^^^^
  File "/home/runner/BonusManager360/app.py", line 145, in not_found_error
    return render_template('errors/404.html'), 404
           ^^^^^^^^^^^^^^^^^^^^^^^^^^^^^^^^^^
  File "/home/runner/BonusManager360/.pythonlibs/lib/python3.11/site-packages/flask/templating.py", line 152, in render_template
    return _render(app, template, context)
           ^^^^^^^^^^^^^^^^^^^^^^^^^^^^^^^
  File "/home/runner/BonusManager360/.pythonlibs/lib/python3.11/site-packages/flask/templating.py", line 133, in _render
    rv = template.render(context)
         ^^^^^^^^^^^^^^^^^^^^^^^^
  File "/home/runner/BonusManager360/.pythonlibs/lib/python3.11/site-packages/jinja2/environment.py", line 1304, in render
    self.environment.handle_exception()
  File "/home/runner/BonusManager360/.pythonlibs/lib/python3.11/site-packages/jinja2/environment.py", line 939, in handle_exception
    raise rewrite_traceback_stack(source=source)
  File "/home/runner/BonusManager360/templates/errors/404.html", line 1, in top-level template code
    {% extends "base.html" %}
  File "/home/runner/BonusManager360/templates/base.html", line 34, in top-level template code
    <a class="nav-link" href="{{ url_for('admin_index') }}">Admin Panel</a>
    ^^^^^^^^^^^^^^^^^^^^^^^^^
  File "/home/runner/BonusManager360/.pythonlibs/lib/python3.11/site-packages/flask/app.py", line 1071, in url_for
    return self.handle_url_build_error(error, endpoint, values)
           ^^^^^^^^^^^^^^^^^^^^^^^^^^^^^^^^^^^^^^^^^^^^^^^^^^^^
  File "/home/runner/BonusManager360/.pythonlibs/lib/python3.11/site-packages/flask/app.py", line 1060, in url_for
    rv = url_adapter.build(  # type: ignore[union-attr]
         ^^^^^^^^^^^^^^^^^^^^^^^^^^^^^^^^^^^^^^^^^^^^^^
  File "/home/runner/BonusManager360/.pythonlibs/lib/python3.11/site-packages/werkzeug/routing/map.py", line 919, in build
    raise BuildError(endpoint, values, method, self)
werkzeug.routing.exceptions.BuildError: Could not build url for endpoint 'admin_index'. Did you mean 'admin.index' instead?
2024-10-25 00:37:33,614 ERROR: Server Error: 500 Internal Server Error: The server encountered an internal error and was unable to complete your request. Either the server is overloaded or there is an error in the application. [in /home/runner/BonusManager360/app.py:150]
2024-10-25 00:39:38,957 INFO: Customer Bonus startup [in /home/runner/BonusManager360/app.py:23]
2024-10-25 00:39:38,957 INFO: Attempting to connect to Redis [in /home/runner/BonusManager360/app.py:60]
2024-10-25 00:39:38,963 WARNING: Redis connection attempt 1 failed: Error -2 connecting to redis-xxxxx.redis.pythonanywhere-services.com:6379. Name or service not known.. Retrying in 2s... [in /home/runner/BonusManager360/app.py:71]
2024-10-25 00:39:40,968 WARNING: Redis connection attempt 2 failed: Error -2 connecting to redis-xxxxx.redis.pythonanywhere-services.com:6379. Name or service not known.. Retrying in 4s... [in /home/runner/BonusManager360/app.py:71]
2024-10-25 00:39:44,973 ERROR: Failed to connect to Redis after 3 attempts [in /home/runner/BonusManager360/app.py:74]
2024-10-25 00:39:44,973 WARNING: Redis connection failed, falling back to database-only notifications [in /home/runner/BonusManager360/app.py:90]
2024-10-25 00:39:44,973 INFO: Using DATABASE_URL for database connection [in /home/runner/BonusManager360/app.py:101]
2024-10-25 00:39:50,378 INFO: Database initialized successfully [in /home/runner/BonusManager360/extensions.py:36]
2024-10-25 00:39:50,609 INFO: Extensions initialized successfully [in /home/runner/BonusManager360/app.py:163]
